Traceback (most recent call last):
  File "/opt/homebrew/lib/python3.10/site-packages/jupyter_cache/executors/utils.py", line 51, in single_nb_execution
    executenb(
  File "/opt/homebrew/lib/python3.10/site-packages/nbclient/client.py", line 1204, in execute
    return NotebookClient(nb=nb, resources=resources, km=km, **kwargs).execute()
  File "/opt/homebrew/lib/python3.10/site-packages/nbclient/util.py", line 84, in wrapped
    return just_run(coro(*args, **kwargs))
  File "/opt/homebrew/lib/python3.10/site-packages/nbclient/util.py", line 62, in just_run
    return loop.run_until_complete(coro)
  File "/opt/homebrew/Cellar/python@3.10/3.10.6_2/Frameworks/Python.framework/Versions/3.10/lib/python3.10/asyncio/base_events.py", line 646, in run_until_complete
    return future.result()
  File "/opt/homebrew/lib/python3.10/site-packages/nbclient/client.py", line 663, in async_execute
    await self.async_execute_cell(
  File "/opt/homebrew/lib/python3.10/site-packages/nbclient/client.py", line 965, in async_execute_cell
    await self._check_raise_for_error(cell, cell_index, exec_reply)
  File "/opt/homebrew/lib/python3.10/site-packages/nbclient/client.py", line 862, in _check_raise_for_error
    raise CellExecutionError.from_cell_and_msg(cell, exec_reply_content)
nbclient.exceptions.CellExecutionError: An error occurred while executing the following cell:
------------------
conda install -c anaconda git
------------------

[0;31m---------------------------------------------------------------------------[0m
[0;31mValueError[0m                                Traceback (most recent call last)
Cell [0;32mIn [1], line 1[0m
[0;32m----> 1[0m get_ipython()[38;5;241m.[39mrun_line_magic([38;5;124m'[39m[38;5;124mconda[39m[38;5;124m'[39m, [38;5;124m'[39m[38;5;124minstall -c anaconda git[39m[38;5;124m'[39m)

File [0;32m/opt/homebrew/lib/python3.10/site-packages/IPython/core/interactiveshell.py:2309[0m, in [0;36mInteractiveShell.run_line_magic[0;34m(self, magic_name, line, _stack_depth)[0m
[1;32m   2307[0m     kwargs[[38;5;124m'[39m[38;5;124mlocal_ns[39m[38;5;124m'[39m] [38;5;241m=[39m [38;5;28mself[39m[38;5;241m.[39mget_local_scope(stack_depth)
[1;32m   2308[0m [38;5;28;01mwith[39;00m [38;5;28mself[39m[38;5;241m.[39mbuiltin_trap:
[0;32m-> 2309[0m     result [38;5;241m=[39m [43mfn[49m[43m([49m[38;5;241;43m*[39;49m[43margs[49m[43m,[49m[43m [49m[38;5;241;43m*[39;49m[38;5;241;43m*[39;49m[43mkwargs[49m[43m)[49m
[1;32m   2310[0m [38;5;28;01mreturn[39;00m result

File [0;32m/opt/homebrew/lib/python3.10/site-packages/IPython/core/magics/packaging.py:87[0m, in [0;36mPackagingMagics.conda[0;34m(self, line)[0m
[1;32m     81[0m [38;5;124;03m"""Run the conda package manager within the current kernel.[39;00m
[1;32m     82[0m 
[1;32m     83[0m [38;5;124;03mUsage:[39;00m
[1;32m     84[0m [38;5;124;03m  %conda install [pkgs][39;00m
[1;32m     85[0m [38;5;124;03m"""[39;00m
[1;32m     86[0m [38;5;28;01mif[39;00m [38;5;129;01mnot[39;00m _is_conda_environment():
[0;32m---> 87[0m     [38;5;28;01mraise[39;00m [38;5;167;01mValueError[39;00m([38;5;124m"[39m[38;5;124mThe python kernel does not appear to be a conda environment.  [39m[38;5;124m"[39m
[1;32m     88[0m                      [38;5;124m"[39m[38;5;124mPlease use ``[39m[38;5;124m%[39m[38;5;124mpip install`` instead.[39m[38;5;124m"[39m)
[1;32m     90[0m conda [38;5;241m=[39m _get_conda_executable()
[1;32m     91[0m args [38;5;241m=[39m shlex[38;5;241m.[39msplit(line)

[0;31mValueError[0m: The python kernel does not appear to be a conda environment.  Please use ``%pip install`` instead.
ValueError: The python kernel does not appear to be a conda environment.  Please use ``%pip install`` instead.

